Workbook

Sheet malumot
A1: audit_id | B1: pws_id | C1: period_start | D1: service_connections | E1: mains_miles | F1: validity_score | G1: real_losses_af | H1: real_losses_cost_usd | I1: nrw_percent | J1: real_losses_gcd | K1: supplier_name | L1: city | M1: yil
A2: 1 | B2: CA0110001 | C2: 2016-01-01 | D2: 84189 | E2: 906.0587 | F2: 51 | G2: 1076.6546 | H2: 599917.43 | I2: 5.4008643 | J2: 11.416875 | K2: Alameda County Water District | L2: Fremont | M2: 2016
A3: 2 | B3: CA0110001 | C3: 2017-01-01 | D3: 84955 | E3: 909.6 | F3: 53 | G3: 2432.33 | H3: 1623863.5 | I3: 8.8991415 | J3: 25.630155 | K3: Alameda County Water District | L3: Fremont | M3: 2017
A4: 3 | B4: CA0110001 | C4: 2018-01-01 | D4: 86250 | E4: 946.84 | F4: 56 | G4: 2630.9711 | H4: 1561830.2 | I4: 8.8323434 | J4: 27.307041 | K4: Alameda County Water District | L4: Fremont | M4: 2018
A5: 4 | B5: CA0110001 | C5: 2019-01-01 | D5: 85825 | E5: 948.5 | F5: 60 | G5: 2467.2471 | H5: 1894013 | I5: 8.5145914 | J5: 25.734546 | K5: Alameda County Water District | L5: Fremont | M5: 2019
A6: 5 | B6: CA0110001 | C6: 2020-01-01 | D6: 86437 | E6: 960.72 | F6: 65 | G6: 2470.7848 | H6: 1936468.9 | I6: 8.2371844 | J6: 25.51887 | K6: Alameda County Water District | L6: Fremont | M6: 2020
A7: 6 | B7: CA0110001 | C7: 2021-01-01 | D7: 86852 | E7: 963.63 | F7: 62 | G7: 2092.5372 | H7: 1818378.3 | I7: 7.5768142 | J7: 21.568057 | K7: Alameda County Water District | L7: Fremont | M7: 2021
A8: 7 | B8: CA0110001 | C8: 2022-01-01 | D8: 87366 | E8: 965.71 | F8: 64 | G8: 1717.2228 | H8: 1474996.6 | I8: 7.0347413 | J8: 17.59551 | K8: Alameda County Water District | L8: Fremont | M8: 2022
A9: 8 | B9: CA0110001 | C9: 2023-01-01 | D9: 88391 | E9: 966.59 | F9: 57 | G9: 1385.7043 | H9: 1609981.3 | I9: 6.3433211 | J9: 14.033959 | K9: Alameda County Water District | L9: Fremont | M9: 2023
A10: 9 | B10: CA0110001 | C10: 2024-01-01 | D10: 88634 | E10: 967.69 | F10: 77 | G10: 1565.9401 | H10: 1773153.9 | I10: 5.2552465 | J10: 15.772516 | K10: Alameda County Water District | L10: Fremont | M10: 2024
A11: 10 | B11: CA0110003 | C11: 2016-01-01 | D11: 19117 | E11: 233.02 | F11: 58 | G11: 365.16327 | H11: 209636.58 | I11: 7.4100789 | J11: 17.052715 | K11: California Water Service Company Livermore | L11: LIV Livermore | M11: 2016
A12: 11 | B12: CA0110003 | C12: 2017-01-01 | D12: 18785 | E12: 228.8 | F12: 62 | G12: 16.210605 | H12: 20188.688 | I12: 2.9227838 | J12: 0.77251285 | K12: California Water Service Company Livermore | L12: LIV Livermore | M12: 2017
A13: 12 | B13: CA0110003 | C13: 2018-01-01 | D13: 18905 | E13: 229.29 | F13: 63 | G13: 448.84759 | H13: 481279.57 | I13: 7.5872231 | J13: 21.253962 | K13: California Water Service Company Livermore | L13: LIV Livermore | M13: 2018
... A90: 146 | B90: CA0410005 | C90: 2024-01-01 | D90: 3883.4167 | E90: 62.571389 | F90: 71 | G90: 287.32019 | H90: 71747.651 | I90: 13.265842 | J90: 66.050842 | K90: California Water Service Company Oroville | L90: ORO Oroville | M90: 2024
A91: 147 | B91: CA0410006 | C91: 2017-01-01 | D91: 7000 | E91: 200 | F91: 94 | G91: 446.57689 | I91: 11.748818 | J91: 57.110489 | K91: South Feather Water and Power | L91: Oroville | M91: 2017
A92: 148 | B92: CA0410006 | C92: 2018-01-01 | D92: 6804 | E92: 149 | F92: 66 | G92: 478.53642 | H92: 87549.064 | I92: 14.005622 | J92: 62.960528 | K92: South Feather Water and Power | L92: Oroville | M92: 2018
A93: 149 | B93: CA0410006 | C93: 2019-01-01 | D93: 6790 | E93: 149 | F93: 66 | G93: 485.08996 | H93: 38084.668 | I93: 14.331046 | J93: 63.954364 | K93: South Feather Water and Power | L93: Oroville | M93: 2019
A94: 150 | B94: CA0410006 | C94: 2020-01-01 | D94: 6909 | E94: 149 | F94: 66 | G94: 580.25562 | H94: 106158.77 | I94: 14.780853 | J94: 74.977396 | K94: South Feather Water and Power | L94: Oroville | M94: 2020
A95: 151 | B95: CA0410006 | C95: 2021-01-01 | D95: 6872 | E95: 150 | F95: 66 | G95: 531.73425 | H95: 97281.7 | I95: 14.196597 | J95: 69.267443 | K95: South Feather Water and Power | L95: Oroville | M95: 2021
A96: 152 | B96: CA0410006 | C96: 2022-01-01 | D96: 6960 | E96: 150 | F96: 67 | G96: 601.21654 | H96: 35901.912 | I96: 12.956556 | J96: 77.328458 | K96: South Feather Water and Power | L96: Oroville | M96: 2022
A97: 153 | B97: CA0410006 | C97: 2023-01-01 | D97: 6843 | E97: 150 | F97: 64 | G97: 603.66387 | H97: 366159.42 | I97: 13.325786 | J97: 78.970761 | K97: South Feather Water and Power | L97: Oroville | M97: 2023
A98: 154 | B98: CA0410006 | C98: 2024-01-01 | D98: 6878 | E98: 150 | F98: 69 | G98: 523.24378 | H98: 318622.6 | I98: 12.035662 | J98: 67.915374 | K98: South Feather Water and Power | L98: Oroville | M98: 2024
A99: 155 | B99: CA0410007 | C99: 2016-01-01 | D99: 8632 | E99: 177.91 | F99: 52 | G99: 261.45527 | H99: 13804.838 | I99: 8.1784834 | J99: 27.040341 | K99: Paradise Irrigation District | L99: Paradise | M99: 2016
A100: 156 | B100: CA0410007 | C100: 2017-01-01 | D100: 8649 | E100: 177.91 | F100: 58 | G100: 142.43639 | H100: 7613.2252 | I100: 4.5522903 | J100: 14.742555 | K100: Paradise Irrigation District | L100: Paradise | M100: 2017
A101: 157 | B101: CA0410007 | C101: 2018-01-01 | D101: 10546 | E101: 177.9 | F101: 51 | G101: 428.42517 | H101: 33815.599 | I101: 23.692503 | J101: 36.366783 | K101: Paradise Irrigation District | L101: Paradise | M101: 2018
A102: 158 | B102: CA0410007 | C102: 2019-01-01 | D102: 10562 | E102: 175.82 | F102: 35 | G102: 1870 | H102: 217499.7 | I102: 70.948308 | J102: 158.49411 | K102: Paradise Irrigation District | L102: Paradise | M102: 2019
A103: 159 | B103: CA0410007 | C103: 2020-01-01 | D103: 10954 | E103: 176.45 | F103: 34 | G103: 1402.4999 | H103: 140923.19 | I103: 71.534217 | J103: 114.30265 | K103: Paradise Irrigation District | L103: Paradise | M103: 2020
... A395: 602 | B395: CA1510001 | C395: 2016-01-01 | D395: 3875 | E395: 60 | F395: 59 | G395: 351.82202 | H395: 162619.16 | I395: 16.788321 | J395: 81.054571 | K395: Arvin Community Service District | L395: Arvin | M395: 2016
A396: 603 | B396: CA1510001 | C396: 2017-01-01 | D396: 4132 | E396: 62 | F396: 57 | G396: 303.78199 | I396: 15.506219 | J396: 65.814165 | K396: Arvin Community Service District | L396: Arvin | M396: 2017
A397: 604 | B397: CA1510001 | C397: 2018-01-01 | D397: 4132 | E397: 62 | F397: 64 | G397: 268.21077 | H397: 87134.541 | I397: 12.099289 | J397: 58.107684 | K397: Arvin Community Service District | L397: Arvin | M397: 2018
A398: 605 | B398: CA1510001 | C398: 2019-01-01 | D398: 4250 | E398: 65 | F398: 64 | G398: 251.39746 | I398: 11.839537 | J398: 52.952885 | K398: Arvin Community Service District | L398: Arvin | M398: 2019
A399: 606 | B399: CA1510001 | C399: 2020-01-01 | D399: 4250 | E399: 65 | F399: 68 | G399: 175.49468 | I399: 8.8386704 | J399: 36.863895 | K399: Arvin Community Service District | L399: Arvin | M399: 2020
A400: 607 | B400: CA1510001 | C400: 2021-01-01 | D400: 4250 | E400: 65 | F400: 64 | G400: 261.06425 | I400: 11.511785 | J400: 54.989041 | K400: Arvin Community Service District | L400: Arvin | M400: 2021
A401: 608 | B401: CA1510001 | C401: 2022-01-01 | D401: 4550 | E401: 65 | F401: 68 | G401: 201.23579 | H401: 22002.977 | I401: 9.6862215 | J401: 39.59237 | K401: Arvin Community Service District | L401: Arvin | M401: 2022
A402: 609 | B402: CA1510001 | C402: 2023-01-01 | D402: 4362 | E402: 65 | F402: 68 | G402: 129.95776 | H402: 21910.689 | I402: 9.2484056 | J402: 26.67069 | K402: Arvin Community Service District | L402: Arvin | M402: 2023
A403: 610 | B403: CA1510003 | C403: 2016-01-01 | D403: 64668 | E403: 845 | F403: 58 | G403: 2878.8904 | H403: 821664.1 | I403: 7.9996721 | J403: 39.743114 | K403: California Water Service Company Bakersfield | L403: BK Bakersfield | M403: 2016
A404: 611 | B404: CA1510003 | C404: 2017-01-01 | D404: 66373 | E404: 845 | F404: 59 | G404: 4359.583 | H404: 1301509.9 | I404: 10.873593 | J404: 58.799167 | K404: California Water Service Company Bakersfield | L404: BK Bakersfield | M404: 2017
A405: 612 | B405: CA1510003 | C405: 2018-01-01 | D405: 66847 | E405: 880.43921 | F405: 60 | G405: 5093.1944 | H405: 1435934.5 | I405: 11.952661 | J405: 68.206538 | K405: California Water Service Company Bakersfield | L405: BK Bakersfield | M405: 2018
A406: 613 | B406: CA1510003 | C406: 2019-01-01 | D406: 67120 | E406: 883.90009 | F406: 62 | G406: 2100.8663 | H406: 688637.2 | I406: 6.8020417 | J406: 28.019742 | K406: California Water Service Company Bakersfield | L406: BK Bakersfield | M406: 2019
A407: 614 | B407: CA1510003 | C407: 2020-01-01 | D407: 67698.583 | E407: 885.61114 | F407: 62 | G407: 4765.4819 | H407: 1573276.2 | I407: 11.402505 | J407: 62.842497 | K407: California Water Service Company Bakersfield | L407: BK Bakersfield | M407: 2020
...

Sheet pivot_yillar
A1: Yillar bo'yicha pivot jadval, 2016-2024
A2: 2015 va 2025 chala yillar bo'lgani uchun chiqarilgan.
B3: Data
A4: yil | B4: auditlar | C4: o'rtacha NRW % | D4: o'rtacha gal/ulanish/kun | E4: o'rtacha ishonchlilik balli
A5: 2016 | B5: 396 | C5: 9.3618762 | D5: 33.685169 | E5: 61.055556
A6: 2017 | B6: 394 | C6: 9.6087929 | D6: 34.600073 | E6: 62.751269
A7: 2018 | B7: 402 | C7: 9.0552291 | D7: 31.429557 | E7: 64.007463
A8: 2019 | B8: 394 | C8: 9.3158285 | D8: 31.496222 | E8: 65.393401
A9: 2020 | B9: 389 | C9: 9.4324641 | D9: 34.688072 | E9: 65.650386
A10: 2021 | B10: 390 | C10: 8.54488 | D10: 28.763587 | E10: 66.179487
A11: 2022 | B11: 387 | C11: 8.8283261 | D11: 29.851962 | E11: 64.369509
A12: 2023 | B12: 388 | C12: 9.4567259 | D12: 30.794081 | E12: 65.56701
A13: 2024 | B13: 375 | C13: 9.6446911 | D13: 33.041523 | E13: 66.128
A14: Jami | B14: 3515 | C14: 9.2483837 | D14: 32.039486 | E14: 64.550498

Sheet pivot_tizimlar
A1: Tizimlar bo'yicha pivot jadval
A2: Guruhlash tizim nomi bo'yicha. Bir tashkilotning bir necha tizimi birlashadi; pws_id darajasidagi taqqoslash reyting_farqi varag'ida.
B3: Data
A4: supplier_name | B4: auditlar | C4: o'rtacha NRW % | D4: o'rtacha gal/ulanish/kun | E4: o'rtacha ishonchlilik balli
A5: Adelanto City Of | B5: 6 | C5: 15.813071 | D5: 57.600865 | E5: 56.5
A6: Alameda County Water District | B6: 9 | C6: 7.3438053 | D6: 20.508614 | E6: 60.555556
A7: Alco Water Service | B7: 5 | C7: 4.820582 | D7: 15.258569 | E7: 79.2
A8: Alhambra City Of | B8: 9 | C8: 6.2795913 | D8: 19.040332 | E8: 62.777778
A9: Amador Water Agency | B9: 6 | C9: 24.678848 | D9: 37.805417 | E9: 57.833333
A10: American Canyon City Of | B10: 9 | C10: 7.1100295 | D10: 21.380501 | E10: 51.111111
A11: Anaheim City Of | B11: 9 | C11: 5.3857585 | D11: 17.772681 | E11: 71.777778
A12: Anderson City Of | B12: 9 | C12: 13.935386 | D12: 76.36866 | E12: 58
A13: Antioch City Of | B13: 10 | C13: 14.018605 | D13: 11.873441 | E13: 57.8
A14: Apple Valley Ranchos Water Company | B14: 9 | C14: 8.6118665 | D14: 28.209202 | E14: 66.555556
A15: Arcadia City Of | B15: 5 | C15: 8.2071509 | D15: 29.914642 | E15: 62.2
A16: Arcata City Of | B16: 9 | C16: 23.109613 | D16: 47.117755 | E16: 55.888889
... A394: Jami | B394: 3541 | C394: 9.2528408 | D394: 32.073584 | E394: 64.549562

Sheet yillar_nazorat
A1: Yillar bo'yicha nazorat jadvali (Excel formulalari bilan)
A2: Yillik ko'rsatkichlar AVERAGEIFS va COUNTIFS formulalari bilan qayta hisoblangan. Python hisobidan mustaqil, tekshirish uchun. 2015 va 2025 chala yillar, chiqarilgan.
A4: yil | B4: auditlar | C4: o'rtacha NRW % | D4: o'rtacha gal/ulanish/kun | E4: o'rtacha ishonchlilik balli
A5: 2016 | B5: =COUNTIFS(malumot!$M$2:$M$3542,$A5) -> 396 | C5: =AVERAGEIFS(malumot!$I$2:$I$3542,malumot!$M$2:$M$3542,$A5) -> 9.3618762 | D5: =AVERAGEIFS(malumot!$J$2:$J$3542,malumot!$M$2:$M$3542,$A5) -> 33.685169 | E5: =AVERAGEIFS(malumot!$F$2:$F$3542,malumot!$M$2:$M$3542,$A5) -> 61.055556
A6: 2017 | B6: =COUNTIFS(malumot!$M$2:$M$3542,$A6) -> 394 | C6: =AVERAGEIFS(malumot!$I$2:$I$3542,malumot!$M$2:$M$3542,$A6) -> 9.6087929 | D6: =AVERAGEIFS(malumot!$J$2:$J$3542,malumot!$M$2:$M$3542,$A6) -> 34.600073 | E6: =AVERAGEIFS(malumot!$F$2:$F$3542,malumot!$M$2:$M$3542,$A6) -> 62.751269
A7: 2018 | B7: =COUNTIFS(malumot!$M$2:$M$3542,$A7) -> 402 | C7: =AVERAGEIFS(malumot!$I$2:$I$3542,malumot!$M$2:$M$3542,$A7) -> 9.0552291 | D7: =AVERAGEIFS(malumot!$J$2:$J$3542,malumot!$M$2:$M$3542,$A7) -> 31.429557 | E7: =AVERAGEIFS(malumot!$F$2:$F$3542,malumot!$M$2:$M$3542,$A7) -> 64.007463
A8: 2019 | B8: =COUNTIFS(malumot!$M$2:$M$3542,$A8) -> 394 | C8: =AVERAGEIFS(malumot!$I$2:$I$3542,malumot!$M$2:$M$3542,$A8) -> 9.3158285 | D8: =AVERAGEIFS(malumot!$J$2:$J$3542,malumot!$M$2:$M$3542,$A8) -> 31.496222 | E8: =AVERAGEIFS(malumot!$F$2:$F$3542,malumot!$M$2:$M$3542,$A8) -> 65.393401
A9: 2020 | B9: =COUNTIFS(malumot!$M$2:$M$3542,$A9) -> 389 | C9: =AVERAGEIFS(malumot!$I$2:$I$3542,malumot!$M$2:$M$3542,$A9) -> 9.4324641 | D9: =AVERAGEIFS(malumot!$J$2:$J$3542,malumot!$M$2:$M$3542,$A9) -> 34.688072 | E9: =AVERAGEIFS(malumot!$F$2:$F$3542,malumot!$M$2:$M$3542,$A9) -> 65.650386
A10: 2021 | B10: =COUNTIFS(malumot!$M$2:$M$3542,$A10) -> 390 | C10: =AVERAGEIFS(malumot!$I$2:$I$3542,malumot!$M$2:$M$3542,$A10) -> 8.54488 | D10: =AVERAGEIFS(malumot!$J$2:$J$3542,malumot!$M$2:$M$3542,$A10) -> 28.763587 | E10: =AVERAGEIFS(malumot!$F$2:$F$3542,malumot!$M$2:$M$3542,$A10) -> 66.179487
A11: 2022 | B11: =COUNTIFS(malumot!$M$2:$M$3542,$A11) -> 387 | C11: =AVERAGEIFS(malumot!$I$2:$I$3542,malumot!$M$2:$M$3542,$A11) -> 8.8283261 | D11: =AVERAGEIFS(malumot!$J$2:$J$3542,malumot!$M$2:$M$3542,$A11) -> 29.851962 | E11: =AVERAGEIFS(malumot!$F$2:$F$3542,malumot!$M$2:$M$3542,$A11) -> 64.369509
A12: 2023 | B12: =COUNTIFS(malumot!$M$2:$M$3542,$A12) -> 388 | C12: =AVERAGEIFS(malumot!$I$2:$I$3542,malumot!$M$2:$M$3542,$A12) -> 9.4567259 | D12: =AVERAGEIFS(malumot!$J$2:$J$3542,malumot!$M$2:$M$3542,$A12) -> 30.794081 | E12: =AVERAGEIFS(malumot!$F$2:$F$3542,malumot!$M$2:$M$3542,$A12) -> 65.56701
A13: 2024 | B13: =COUNTIFS(malumot!$M$2:$M$3542,$A13) -> 375 | C13: =AVERAGEIFS(malumot!$I$2:$I$3542,malumot!$M$2:$M$3542,$A13) -> 9.6446911 | D13: =AVERAGEIFS(malumot!$J$2:$J$3542,malumot!$M$2:$M$3542,$A13) -> 33.041523 | E13: =AVERAGEIFS(malumot!$F$2:$F$3542,malumot!$M$2:$M$3542,$A13) -> 66.128
A14: Jami | B14: =SUM(B5:B13) -> 3515

Sheet izoh
A1: Varaqlar
A3: Varaq | B3: Nima
A4: malumot | B4: 3541 audit, 13 ustun. Pivot jadvallar uchun manba.
A5: pivot_yillar | B5: Yillar bo'yicha, 2016-2024.
A6: pivot_tizimlar | B6: 428 tizim bo'yicha, tizim nomi darajasida.
A7: yillar_nazorat | B7: Yillik ko'rsatkichlar formulalar bilan mustaqil hisoblangan.
A8: reyting_farqi | B8: Ikki ko'rsatkich bo'yicha o'rinlar farqi, pws_id darajasida.
A11: Ustunlar
A12: nrw_percent | B12: hisobga olinmagan suv / tizimga berilgan suv x 100
A13: real_losses_gcd | B13: real yo'qotish, bir ulanishga kuniga, gallon
A14: validity_score | B14: audit ishonchliligi balli, 0-100. O'lchov sifatini ko'rsatadi, yo'qotish miqdorini emas
A15: real_losses_cost_usd | B15: manbadagi yillik zarar, dollar. 31 auditda bo'sh
A16: yil | B16: period_start dan olingan
A19: Manba: CA DWR, tasdiqlangan suv yo'qotish auditlari, 2026-09-04. Chegaralar: zichlik >= 30, ulanishlar >= 3000.

Sheet reyting_farqi
A1: Ikki ko'rsatkich, ikki xil reyting
A2: Har bir tizim uchun ikkala ko'rsatkichning yillar bo'yicha o'rtachasi olindi va 428 tizim ichida o'rni belgilandi. Ro'yxat o'rinlar farqi bo'yicha kamayish tartibida.
A4: pws_id | B4: tizim nomi | C4: o'rtacha NRW % | D4: o'rtacha gal/ulanish/kun | E4: o'rin (foiz) | F4: o'rin (gallon) | G4: o'rinlar farqi
A5: CA3610008 | B5: Big Bear Community Services District | C5: =AVERAGEIFS(malumot!$I$2:$I$3542,malumot!$B$2:$B$3542,$A5) -> 15.030188 | D5: =AVERAGEIFS(malumot!$J$2:$J$3542,malumot!$B$2:$B$3542,$A5) -> 12.456723 | E5: =RANK(C5,$C$5:$C$432,0) -> 51 | F5: =RANK(D5,$D$5:$D$432,0) -> 368 | G5: =ABS(E5-F5) -> 317
A6: CA0710001 | B6: Antioch City Of | C6: =AVERAGEIFS(malumot!$I$2:$I$3542,malumot!$B$2:$B$3542,$A6) -> 14.018605 | D6: =AVERAGEIFS(malumot!$J$2:$J$3542,malumot!$B$2:$B$3542,$A6) -> 11.873441 | E6: =RANK(C6,$C$5:$C$432,0) -> 61 | F6: =RANK(D6,$D$5:$D$432,0) -> 373 | G6: =ABS(E6-F6) -> 312
A7: CA4010014 | B7: Cambria Community Service District | C7: =AVERAGEIFS(malumot!$I$2:$I$3542,malumot!$B$2:$B$3542,$A7) -> 15.638673 | D7: =AVERAGEIFS(malumot!$J$2:$J$3542,malumot!$B$2:$B$3542,$A7) -> 13.463966 | E7: =RANK(C7,$C$5:$C$432,0) -> 48 | F7: =RANK(D7,$D$5:$D$432,0) -> 360 | G7: =ABS(E7-F7) -> 312
A8: CA5510009 | B8: Groveland Community Services District | C8: =AVERAGEIFS(malumot!$I$2:$I$3542,malumot!$B$2:$B$3542,$A8) -> 20.60398 | D8: =AVERAGEIFS(malumot!$J$2:$J$3542,malumot!$B$2:$B$3542,$A8) -> 16.142915 | E8: =RANK(C8,$C$5:$C$432,0) -> 22 | F8: =RANK(D8,$D$5:$D$432,0) -> 326 | G8: =ABS(E8-F8) -> 304
A9: CA2410004 | B9: Livingston City Of | C9: =AVERAGEIFS(malumot!$I$2:$I$3542,malumot!$B$2:$B$3542,$A9) -> 6.0785396 | D9: =AVERAGEIFS(malumot!$J$2:$J$3542,malumot!$B$2:$B$3542,$A9) -> 74.657901 | E9: =RANK(C9,$C$5:$C$432,0) -> 311 | F9: =RANK(D9,$D$5:$D$432,0) -> 28 | G9: =ABS(E9-F9) -> 283
A10: CA3610044 | B10: Big Bear Lake City Of | C10: =AVERAGEIFS(malumot!$I$2:$I$3542,malumot!$B$2:$B$3542,$A10) -> 11.206103 | D10: =AVERAGEIFS(malumot!$J$2:$J$3542,malumot!$B$2:$B$3542,$A10) -> 10.629363 | E10: =RANK(C10,$C$5:$C$432,0) -> 105 | F10: =RANK(D10,$D$5:$D$432,0) -> 384 | G10: =ABS(E10-F10) -> 279
A11: CA3610015 | B11: Crestline Village Water District | C11: =AVERAGEIFS(malumot!$I$2:$I$3542,malumot!$B$2:$B$3542,$A11) -> 10.05686 | D11: =AVERAGEIFS(malumot!$J$2:$J$3542,malumot!$B$2:$B$3542,$A11) -> 9.5252702 | E11: =RANK(C11,$C$5:$C$432,0) -> 133 | F11: =RANK(D11,$D$5:$D$432,0) -> 394 | G11: =ABS(E11-F11) -> 261
A12: CA0410011 | B12: Del Oro Water Company | C12: =AVERAGEIFS(malumot!$I$2:$I$3542,malumot!$B$2:$B$3542,$A12) -> 21.629831 | D12: =AVERAGEIFS(malumot!$J$2:$J$3542,malumot!$B$2:$B$3542,$A12) -> 20.494424 | E12: =RANK(C12,$C$5:$C$432,0) -> 21 | F12: =RANK(D12,$D$5:$D$432,0) -> 269 | G12: =ABS(E12-F12) -> 248
A13: CA3610005 | B13: Lake Arrowhead Community Services District | C13: =AVERAGEIFS(malumot!$I$2:$I$3542,malumot!$B$2:$B$3542,$A13) -> 14.977225 | D13: =AVERAGEIFS(malumot!$J$2:$J$3542,malumot!$B$2:$B$3542,$A13) -> 18.649104 | E13: =RANK(C13,$C$5:$C$432,0) -> 53 | F13: =RANK(D13,$D$5:$D$432,0) -> 298 | G13: =ABS(E13-F13) -> 245
A14: CA4010026 | B14: Nipomo Community Service District | C14: =AVERAGEIFS(malumot!$I$2:$I$3542,malumot!$B$2:$B$3542,$A14) -> 11.937284 | D14: =AVERAGEIFS(malumot!$J$2:$J$3542,malumot!$B$2:$B$3542,$A14) -> 15.669943 | E14: =RANK(C14,$C$5:$C$432,0) -> 88 | F14: =RANK(D14,$D$5:$D$432,0) -> 332 | G14: =ABS(E14-F14) -> 244
A15: CA3610062 | B15: Running Springs Water District | C15: =AVERAGEIFS(malumot!$I$2:$I$3542,malumot!$B$2:$B$3542,$A15) -> 9.7345048 | D15: =AVERAGEIFS(malumot!$J$2:$J$3542,malumot!$B$2:$B$3542,$A15) -> 10.364214 | E15: =RANK(C15,$C$5:$C$432,0) -> 144 | F15: =RANK(D15,$D$5:$D$432,0) -> 388 | G15: =ABS(E15-F15) -> 244
A16: CA4110023 | B16: San Bruno City Of | C16: =AVERAGEIFS(malumot!$I$2:$I$3542,malumot!$B$2:$B$3542,$A16) -> 13.767656 | D16: =AVERAGEIFS(malumot!$J$2:$J$3542,malumot!$B$2:$B$3542,$A16) -> 17.902178 | E16: =RANK(C16,$C$5:$C$432,0) -> 65 | F16: =RANK(D16,$D$5:$D$432,0) -> 306 | G16: =ABS(E16-F16) -> 241
... A432: CA2810003 | B432: Napa City Of | C432: =AVERAGEIFS(malumot!$I$2:$I$3542,malumot!$B$2:$B$3542,$A432) -> 8.3366525 | D432: =AVERAGEIFS(malumot!$J$2:$J$3542,malumot!$B$2:$B$3542,$A432) -> 27.505284 | E432: =RANK(C432,$C$5:$C$432,0) -> 199 | F432: =RANK(D432,$D$5:$D$432,0) -> 199 | G432: =ABS(E432-F432) -> 0
